Epoch 1/3:   0%|                                                                                                                                                                          | 0/1 [00:00<?, ?it/s]
Traceback (most recent call last):
  File "/Users/akshay/Desktop/DSU/cot2.py", line 224, in <module>
    train_advanced_cot_model(cot_model, train_dataloader, epochs=3, lr=1e-5, fp16=True)
  File "/Users/akshay/Desktop/DSU/cot2.py", line 151, in train_advanced_cot_model
    for step, batch in enumerate(train_dataloader):
  File "/Users/akshay/Desktop/DSU/.venv/lib/python3.11/site-packages/torch/utils/data/dataloader.py", line 630, in __next__
    data = self._next_data()
           ^^^^^^^^^^^^^^^^^
  File "/Users/akshay/Desktop/DSU/.venv/lib/python3.11/site-packages/torch/utils/data/dataloader.py", line 673, in _next_data
    data = self._dataset_fetcher.fetch(index)  # may raise StopIteration
           ^^^^^^^^^^^^^^^^^^^^^^^^^^^^^^^^^^
  File "/Users/akshay/Desktop/DSU/.venv/lib/python3.11/site-packages/torch/utils/data/_utils/fetch.py", line 52, in fetch
    data = [self.dataset[idx] for idx in possibly_batched_index]
           ^^^^^^^^^^^^^^^^^^^^^^^^^^^^^^^^^^^^^^^^^^^^^^^^^^^^^
  File "/Users/akshay/Desktop/DSU/.venv/lib/python3.11/site-packages/torch/utils/data/_utils/fetch.py", line 52, in <listcomp>
    data = [self.dataset[idx] for idx in possibly_batched_index]
            ~~~~~~~~~~~~^^^^^
  File "/Users/akshay/Desktop/DSU/cot2.py", line 23, in __getitem__
    item = self.dataset[idx]
           ^^^^^^^^^^^^
AttributeError: 'ChainOfThoughtDataset' object has no attribute 'dataset'
